<?xml version="1.0"?>
<robot xmlns:xacro="http://www.ros.org/wiki/xacro" name="arm">
<link name="world"/>

<link name="base">
    <visual>
      <geometry>
      	<box size="0.3 0.3 0.001"/>
      </geometry>
    <origin xyz="0 0 0" rpy="0 0 0"/>
    </visual>
	<collision>
    <origin xyz="0 0 0" rpy="0 0 0"/>
      		<geometry>
      	<box size="0.004 0.002 0.001"/>
      		</geometry>
	</collision>
	<inertial>
    <origin xyz="0 0 0" rpy="0 0 0"/>
          <mass value="100" />
          <inertia ixx="0.5" ixy="0" ixz="0" iyy="0.5" iyz="0" izz="2"/>
    </inertial>
  </link>


  <link name="turn_table">
    <visual>
      <geometry>
      	<cylinder radius="0.05" length="0.045"/>
      </geometry>
    <origin xyz="0 0 0" rpy="0 0 0"/>
    </visual>

	<inertial>
    <origin xyz="0 0 0" rpy="0 0 0"/>
          <mass value="20" />
          <inertia ixx="0.02" ixy="0" ixz="0" iyy="0.02" iyz="0" izz="0.02"/>
    </inertial>
  </link>

  <link name="lower_arm">
    <visual>
      <geometry>
      	<cylinder radius="0.01" length="0.19"/>
      </geometry>
    <origin xyz="0 0 0.095" rpy="0 0 0"/>
    </visual>

	<inertial>
    <origin xyz="0 0 0.095" rpy="0 0 0"/>
          <mass value="10" />
          <inertia ixx="0.025" ixy="0" ixz="0" iyy="0.025" iyz="0" izz="0.001"/>
    </inertial>
  </link>

  <link name="upper_arm">
    <visual>
      <geometry>
      	<cylinder radius="0.01" length="0.2"/>
      </geometry>
    <origin xyz="-0.004 0.1 0.025" rpy="1.57 0 0"/>
    </visual>

	<inertial>
    <origin xyz="-0.004 0.1 0.025" rpy="0 0 0"/>
          <mass value="10" />
          <inertia ixx="0.025" ixy="0" ixz="0" iyy="0.001" iyz="0" izz="0.025"/>
    </inertial>
  </link> 


<link name="wrist_z">
    <visual>
      <geometry>
      	<box size="0.02 0.01 0.025"/>
      </geometry>
    <origin xyz="0.0 0.005 0" rpy="0 0 0"/>
    </visual>

	<inertial>
    <origin xyz="0.0 0.005 0" rpy="0 0 0"/>
          <mass value="1" />
          <inertia ixx="0.005" ixy="0" ixz="0" iyy="0.005" iyz="0" izz="0.005"/>
    </inertial>
  </link>

 
  <link name="wrist_x">
    <visual>
      <geometry>
      	<box size="0.025 0.02 0.01"/>
      </geometry>
    <origin xyz="0 0 -0.005" rpy="0 0 0"/>
    </visual>

	<inertial>
    <origin xyz="0 0 -0.005" rpy="0 0 0"/>
          <mass value="1" />
          <inertia ixx="0.005" ixy="0" ixz="0" iyy="0.005" iyz="0" izz="0.005"/>
    </inertial>
  </link> 

  <link name="end_effector1">
    <visual>
      <geometry>
      	<box size="0.03 0.006 0.04"/>
      </geometry>
    <origin xyz="0.015 0 -0.02" rpy="0 0 0"/>
    </visual>

	<inertial>
    <origin xyz="0.015 0 -0.02" rpy="0 0 0"/>
          <mass value="1" />
          <inertia ixx="0.005" ixy="0" ixz="0" iyy="0.005" iyz="0" izz="0.005"/>
    </inertial>
  </link> 

  <link name="end_effector2">
    <visual>
      <geometry>
      	<box size="0.03 0.06 0.008"/>
      </geometry>
    <origin xyz="0 0 0" rpy="0 0 0"/>
    </visual>

	<inertial>
    <origin xyz="0 0 0" rpy="0 0 0"/>
          <mass value="1" />
          <inertia ixx="0.005" ixy="0" ixz="0" iyy="0.005" iyz="0" izz="0.005"/>
    </inertial>
  </link> 


<joint name="fixed_base" type="fixed">
<parent link="world"/>
<child link="base"/>
<origin xyz="0 0 0.0005 "/>
</joint>

<joint name="turn" type="revolute">  <!-- revolute --> <!-- continuous -->
<parent link="base"/>
<child link="turn_table"/>
<axis xyz="0 0 1"/>
<origin xyz="0 0 0.023"/>
<limit effort="500" lower="-3.14" upper="3.14" velocity="6"/>
<dynamics damping="10"/> 
</joint>

<joint name="shoulder" type="revolute"> 
<parent link="turn_table"/>
<child link="lower_arm"/>
<axis xyz="1 0 0"/>
<origin xyz="0.02 0.015 0.0225 "/>
<limit effort="1000" lower="-3.14" upper="3.14" velocity="6"/>
<dynamics damping="10"/> 
</joint>

<joint name="elbow" type="revolute">
<parent link="lower_arm"/>
<child link="upper_arm"/>
<axis xyz="1 0 0"/>
<origin xyz="0.004 0 0.19 "/>
<limit effort="500" lower="-3.14" upper="3.14" velocity="6"/>
<dynamics damping="10"/>
</joint>

 <joint name="wristy" type="revolute">
<parent link="upper_arm"/>
<child link="wrist_z"/>
<axis xyz="0 1 0"/>
<origin xyz="0 0.2 0.035 "/>
<limit effort="20" lower="-3.14" upper="3.14" velocity="3"/>
<dynamics damping="10"/>
</joint>


<joint name="wristz" type="revolute">
<parent link="wrist_z"/>
<child link="wrist_x"/>
<axis xyz="0 0 -1"/>
<origin xyz="0 0.005 -0.015 "/>
<limit effort="20" lower="-3.14" upper="3.14" velocity="3"/>
<dynamics damping="10"/>
</joint>

<joint name="wristx" type="revolute">
<parent link="wrist_x"/>
<child link="end_effector1"/>
<axis xyz="1 0 0"/>
<origin xyz="0.0125 0 0.0 "/>
<limit effort="20" lower="-3.14" upper="3.14" velocity="3"/>
<dynamics damping="10"/>
</joint> 

<joint name="end_effector_fixed" type="revolute">
<parent link="end_effector1"/>
<child link="end_effector2"/>
<axis xyz="1 0 0"/>
<origin xyz="0.0125 0.03 -0.07 "/>
<limit effort="0" lower="0" upper="0" velocity="0"/>
<dynamics damping="10"/>
</joint> 




<transmission name="turn_trans">
<type>transmission_interface/SimpleTransmission</type>
<actuator name="$turn_motor">
<mechanicalReduction>1</mechanicalReduction>
</actuator>
<joint name="turn">
<hardwareInterface>hardware_interface/VelocityJointInterface</hardwareInterface>
</joint>
</transmission>

<transmission name="shoulder_trans">
<type>transmission_interface/SimpleTransmission</type>
<actuator name="$shoulder_motor">
<mechanicalReduction>1</mechanicalReduction>
</actuator>
<joint name="shoulder">
<hardwareInterface>hardware_interface/VelocityJointInterface</hardwareInterface>
</joint>
</transmission>

<transmission name="elbow_trans">
<type>transmission_interface/SimpleTransmission</type>
<actuator name="$elbow_motor">
<mechanicalReduction>1</mechanicalReduction>
</actuator>
<joint name="elbow">
<hardwareInterface>hardware_interface/VelocityJointInterface</hardwareInterface>
</joint>
</transmission>



<transmission name="wristy_trans">
<type>transmission_interface/SimpleTransmission</type>
<actuator name="$wristy_motor">
<mechanicalReduction>1</mechanicalReduction>
</actuator>
<joint name="wristy">
<hardwareInterface>hardware_interface/VelocityJointInterface</hardwareInterface>
</joint>
</transmission>


<transmission name="wristz_trans">
<type>transmission_interface/SimpleTransmission</type>
<actuator name="$wristz_motor">
<mechanicalReduction>1</mechanicalReduction>
</actuator>
<joint name="wristz">
<hardwareInterface>hardware_interface/VelocityJointInterface</hardwareInterface>
</joint>
</transmission>

 <transmission name="wristx_trans">
<type>transmission_interface/SimpleTransmission</type>
<actuator name="$wristx_motor">
<mechanicalReduction>1</mechanicalReduction>
</actuator>
<joint name="wristx">
<hardwareInterface>hardware_interface/VelocityJointInterface</hardwareInterface>
</joint>
</transmission>

 

<gazebo>
  <plugin name="gazebo_ros_control" filename="libgazebo_ros_control.so">
   <robotNamespace>/</robotNamespace>
 </plugin>
</gazebo>


</robot>

